2022-11-12 18:52:04,546 INFO    Thread-3516:847 [wandb_setup.py:_flush():68] Configure stats pid to 847
2022-11-12 18:52:04,547 INFO    Thread-3516:847 [wandb_setup.py:_flush():68] Loading settings from /home/mmendieta/.config/wandb/settings
2022-11-12 18:52:04,547 INFO    Thread-3516:847 [wandb_setup.py:_flush():68] Loading settings from /home/mmendieta/violence_prediction/Scripts/wandb/settings
2022-11-12 18:52:04,547 INFO    Thread-3516:847 [wandb_setup.py:_flush():68] Loading settings from environment variables: {'_require_service': 'True', 'project': 'rf_param_opt', 'entity': 'npsdaor', 'root_dir': '/home/mmendieta/violence_prediction/Scripts', 'run_id': 'pd85bnxm', 'sweep_param_path': '/home/mmendieta/violence_prediction/Scripts/wandb/sweep-8aa3rgqe/config-pd85bnxm.yaml', 'sweep_id': '8aa3rgqe'}
2022-11-12 18:52:04,547 INFO    Thread-3516:847 [wandb_setup.py:_flush():68] Inferring run settings from compute environment: {'program': '<python with no main file>'}
2022-11-12 18:52:04,547 INFO    Thread-3516:847 [wandb_init.py:_log_setup():476] Logging user logs to /home/mmendieta/violence_prediction/Scripts/wandb/run-20221112_185204-pd85bnxm/logs/debug.log
2022-11-12 18:52:04,547 INFO    Thread-3516:847 [wandb_init.py:_log_setup():477] Logging internal logs to /home/mmendieta/violence_prediction/Scripts/wandb/run-20221112_185204-pd85bnxm/logs/debug-internal.log
2022-11-12 18:52:04,548 INFO    Thread-3516:847 [wandb_init.py:_jupyter_setup():426] configuring jupyter hooks <wandb.sdk.wandb_init._WandbInit object at 0x7fccb25676d0>
2022-11-12 18:52:04,548 INFO    Thread-3516:847 [wandb_init.py:init():516] calling init triggers
2022-11-12 18:52:04,548 INFO    Thread-3516:847 [wandb_init.py:init():519] wandb.init called with sweep_config: {'criterion': 'gini', 'min_samples_leaf': 50, 'min_samples_split': 1000, 'n_estimators': 500}
config: {}
2022-11-12 18:52:04,548 INFO    Thread-3516:847 [wandb_init.py:init():569] starting backend
2022-11-12 18:52:04,549 INFO    Thread-3516:847 [wandb_init.py:init():573] setting up manager
2022-11-12 18:52:04,557 INFO    Thread-3516:847 [backend.py:_multiprocessing_setup():102] multiprocessing start_methods=fork,spawn,forkserver, using: spawn
2022-11-12 18:52:04,560 INFO    Thread-3516:847 [wandb_init.py:init():580] backend started and connected
2022-11-12 18:52:04,578 INFO    Thread-3516:847 [wandb_run.py:_config_callback():1160] config_cb None None {'criterion': 'gini', 'min_samples_leaf': 50, 'min_samples_split': 1000, 'n_estimators': 500}
2022-11-12 18:52:04,581 INFO    Thread-3516:847 [wandb_run.py:_label_probe_notebook():1113] probe notebook
2022-11-12 18:52:04,581 INFO    Thread-3516:847 [wandb_run.py:_label_probe_notebook():1123] Unable to probe notebook: 'NoneType' object has no attribute 'get'
2022-11-12 18:52:04,581 INFO    Thread-3516:847 [wandb_init.py:init():658] updated telemetry
2022-11-12 18:52:04,672 INFO    Thread-3516:847 [wandb_init.py:init():693] communicating run to backend with 60 second timeout
2022-11-12 18:52:05,043 INFO    Thread-3516:847 [wandb_run.py:_on_init():2000] communicating current version
2022-11-12 18:52:05,125 INFO    Thread-3516:847 [wandb_run.py:_on_init():2004] got version response upgrade_message: "wandb version 0.13.5 is available!  To upgrade, please run:\n $ pip install wandb --upgrade"

2022-11-12 18:52:05,125 INFO    Thread-3516:847 [wandb_init.py:init():728] starting run threads in backend
2022-11-12 18:52:05,260 INFO    Thread-3516:847 [wandb_run.py:_console_start():1980] atexit reg
2022-11-12 18:52:05,260 INFO    Thread-3516:847 [wandb_run.py:_redirect():1838] redirect: SettingsConsole.WRAP_RAW
2022-11-12 18:52:05,261 INFO    Thread-3516:847 [wandb_run.py:_redirect():1903] Wrapping output streams.
2022-11-12 18:52:05,261 INFO    Thread-3516:847 [wandb_run.py:_redirect():1925] Redirects installed.
2022-11-12 18:52:05,262 INFO    Thread-3516:847 [wandb_init.py:init():765] run started, returning control to user process
2022-11-12 19:03:54,453 ERROR   Thread-1460:847 [internal_api.py:execute():216] 500 response executing GraphQL.
2022-11-12 19:03:54,453 ERROR   Thread-1460:847 [internal_api.py:execute():217] {"error":"driver: bad connection"}
2022-11-12 19:04:50,676 ERROR   Thread-1460:847 [internal_api.py:execute():216] 500 response executing GraphQL.
2022-11-12 19:04:50,677 ERROR   Thread-1460:847 [internal_api.py:execute():217] {"error":"context deadline exceeded"}
2022-11-12 19:05:16,837 ERROR   Thread-1460:847 [internal_api.py:execute():216] 500 response executing GraphQL.
2022-11-12 19:05:16,837 ERROR   Thread-1460:847 [internal_api.py:execute():217] {"error":"driver: bad connection"}
2022-11-12 19:05:16,838 ERROR   Thread-1460:847 [retry.py:__call__():154] Retry attempt failed:
Traceback (most recent call last):
  File "/home/mmendieta/transformers/lib/python3.8/site-packages/wandb/sdk/lib/retry.py", line 113, in __call__
    result = self._call_fn(*args, **kwargs)
  File "/home/mmendieta/transformers/lib/python3.8/site-packages/wandb/sdk/internal/internal_api.py", line 213, in execute
    return self.client.execute(*args, **kwargs)  # type: ignore
  File "/home/mmendieta/transformers/lib/python3.8/site-packages/wandb/vendor/gql-0.2.0/wandb_gql/client.py", line 52, in execute
    result = self._get_result(document, *args, **kwargs)
  File "/home/mmendieta/transformers/lib/python3.8/site-packages/wandb/vendor/gql-0.2.0/wandb_gql/client.py", line 60, in _get_result
    return self.transport.execute(document, *args, **kwargs)
  File "/home/mmendieta/transformers/lib/python3.8/site-packages/wandb/vendor/gql-0.2.0/wandb_gql/transport/requests.py", line 39, in execute
    request.raise_for_status()
  File "/usr/local/miniconda3/lib/python3.8/site-packages/requests/models.py", line 941, in raise_for_status
    raise HTTPError(http_error_msg, response=self)
requests.exceptions.HTTPError: 500 Server Error: Internal Server Error for url: https://api.wandb.ai/graphql
2022-11-12 19:05:29,862 ERROR   Thread-1460:847 [internal_api.py:execute():216] 500 response executing GraphQL.
2022-11-12 19:05:29,862 ERROR   Thread-1460:847 [internal_api.py:execute():217] {"error":"driver: bad connection"}
2022-11-12 19:15:45,558 INFO    Thread-3516:847 [wandb_run.py:_finish():1746] finishing run npsdaor/rf_param_opt/pd85bnxm
2022-11-12 19:15:45,559 INFO    Thread-3516:847 [jupyter.py:save_history():448] not saving jupyter history
2022-11-12 19:15:45,559 INFO    Thread-3516:847 [jupyter.py:save_ipynb():378] not saving jupyter notebook
2022-11-12 19:15:45,559 INFO    Thread-3516:847 [wandb_init.py:_jupyter_teardown():408] cleaning up jupyter logic
2022-11-12 19:15:45,560 INFO    Thread-3516:847 [wandb_run.py:_atexit_cleanup():1949] got exitcode: 0
2022-11-12 19:15:45,560 INFO    Thread-3516:847 [wandb_run.py:_restore():1932] restore
2022-11-12 19:15:45,560 INFO    Thread-3516:847 [wandb_run.py:_restore():1938] restore done
2022-11-12 19:15:49,258 INFO    Thread-3516:847 [wandb_run.py:_footer_history_summary_info():3377] rendering history
2022-11-12 19:15:49,259 INFO    Thread-3516:847 [wandb_run.py:_footer_history_summary_info():3409] rendering summary
2022-11-12 19:15:49,270 INFO    Thread-3516:847 [wandb_run.py:_footer_sync_info():3333] logging synced files
